<?xml version="1.0"?>
<gazebo version="1.0">
  <world name="default">
    <scene>
      <ambient rgba="0.1 0.1 0.1 1"/>
      <background rgba="0 0 0 1"/>
      <shadows enabled="false"/>
    </scene>

    <physics type="ode">
      <gravity xyz="0 0 -9.8"/>
      <ode>
        <solver type="quick" dt="0.01" iters="100" sor="1.3"/>
      </ode>
    </physics>

    <!-- Ground Plane -->
    <model name="plane1_model" static="false">
      <link name="body">
        <inertial mass="1.0">
          <inertia ixx="1" ixy="0" ixz="0" iyy="1" iyz="0" izz="1"/>
        </inertial>
        <collision name="geom">
          <geometry>
            <plane normal="0 0 1"/>
          </geometry>
          <surface>
            <friction>
              <ode mu="0" mu2="0"/>
            </friction>
          </surface>
        </collision>
       <visual name="visual" cast_shadows="false">
          <geometry>
            <plane normal="0 0 1"/>
          </geometry>
          <material script="Gazebo/Gold"/>
        </visual>
      </link>
    </model>
    
    <!-- model robot -->
    <model name="box">
      <origin pose="0 2.5 0 0 0 0"/>
      <!--boxGreen link-->
      <link name='boxGreen'>
        <pose>0 0 0 0 0 0</pose>
        <collision name="collision">
          <geometry>
            <box>
              <size>0.3 0.3 0.3</size>
            </box>
          </geometry>
        </collision>

        <visual name="visual">
          <geometry>
            <box>
              <size>0.3 0.3 0.3</size>
            </box>
          </geometry>
          <material>
            <ambient>0 1 0 1</ambient>
            <diffuse>0 1 0 1</diffuse>
            <specular>0.1 0.1 0.1 1</specular>
            <emissive>0 0 0 0</emissive>
          </material>
        </visual>
      </link>

      <!--boxBlue1 link-->
      <link name="boxBlue1">
        <pose>0.4 0 0 0 0 0</pose>
        <collision name="collision">
          <geometry>
            <box>
              <size>0.3 0.3 0.3</size>
            </box>
          </geometry>
        </collision>

        <visual name="visual">
          <geometry>
            <box>
              <size>0.3 0.3 0.3</size>
            </box>
          </geometry>
          <material>
            <ambient>0 0 1 1</ambient>
            <diffuse>0 0 1 1</diffuse>
            <specular>0.1 0.1 0.1 1</specular>
            <emissive>0 0 0 0</emissive>
          </material>
        </visual>
      </link>

      <!--boxBlue2 link-->
      <link name="boxBlue2">
        <pose>-0.4 0 0 0 0 0</pose>
        <collision name="collision">
          <geometry>
            <box>
              <size>0.3 0.3 0.3</size>
            </box>
          </geometry>
        </collision>

        <visual name="visual">
          <geometry>
            <box>
              <size>0.3 0.3 0.3</size>
            </box>
          </geometry>
          <material>
            <ambient>0 0 1 1</ambient>
            <diffuse>0 0 1 1</diffuse>
            <specular>0.1 0.1 0.1 1</specular>
            <emissive>0 0 0 0</emissive>
          </material>
        </visual>
      </link>
    </model>

    <!-- ThymioCamera -->
    <model name="ThymioCamera">
    <static>false</static>
      <link name='chassis'>
        <pose>0 0 .1 0 0 0</pose>

        <collision name='collision'>
          <geometry>
            <box>
              <size>.4 .2 .1</size>
            </box>
          </geometry>
        </collision>

        <visual name='visual'>
          <geometry>
            <box>
              <size>.4 .2 .1</size>
            </box>
          </geometry>
        </visual>
        <collision name='caster_collision'>
          <pose>-0.15 0 -0.05 0 0 0</pose>
          <geometry>
              <sphere>
              <radius>.05</radius>
            </sphere>
          </geometry>

          <surface>
            <friction>
              <ode>
                <mu>0</mu>
                <mu2>0</mu2>
                <slip1>1.0</slip1>
                <slip2>1.0</slip2>
              </ode>
            </friction>
          </surface>
        </collision>

        <visual name='caster_visual'>
          <pose>-0.15 0 -0.05 0 0 0</pose>
          <geometry>
            <sphere>
              <radius>.05</radius>
            </sphere>
          </geometry>
        </visual>
      </link>
      <link name="left_wheel">
        <pose>0.1 0.13 0.1 0 1.5707 1.5707</pose>
        <collision name="collision">
          <geometry>
            <cylinder>
              <radius>.1</radius>
              <length>.05</length>
            </cylinder>
          </geometry>
        </collision>
        <visual name="visual">
          <geometry>
            <cylinder>
              <radius>.1</radius>
              <length>.05</length>
            </cylinder>
          </geometry>
        </visual>
      </link>

      <link name="right_wheel">
        <pose>0.1 -0.13 0.1 0 1.5707 1.5707</pose>
        <collision name="collision">
          <geometry>
            <cylinder>
              <radius>.1</radius>
              <length>.05</length>
            </cylinder>
          </geometry>
        </collision>
        <visual name="visual">
          <geometry>
            <cylinder>
              <radius>.1</radius>
              <length>.05</length>
            </cylinder>
          </geometry>
        </visual>
      </link>

      <joint type="revolute" name="left_wheel_hinge">
        <pose>0 0 -0.03 0 0 0</pose>
        <child>left_wheel</child>
        <parent>chassis</parent>
        <axis>
          <xyz>0 1 0</xyz>
        </axis>
      </joint>

      <joint type="revolute" name="right_wheel_hinge">
        <pose>0 0 0.03 0 0 0</pose>
        <child>right_wheel</child>
        <parent>chassis</parent>
        <axis>
          <xyz>0 1 0</xyz>
        </axis>
      </joint>

      <link name="camera">
        <pose>0.2 0 0.2 0 0 0</pose>
        <inertial>
          <mass>0.1</mass>
          <inertia>
            <ixx>0.000166667</ixx>
            <iyy>0.000166667</iyy>
            <izz>0.000166667</izz>
          </inertia>
        </inertial>
        <collision name="collision">
          <geometry>
            <box>
              <size>0.1 0.1 0.1</size>
            </box>
          </geometry>
        </collision>
        <visual name="visual">
          <geometry>
            <box>
              <size>0.1 0.1 0.1</size>
            </box>
          </geometry>
        </visual>
        <sensor name="camera" type="camera">
          <camera>
            <horizontal_fov>1.57</horizontal_fov>
            <image>
              <width>640</width>
              <height>480</height>
            </image>
            <clip>
              <near>0.1</near>
              <far>100</far>
            </clip>
          </camera>
          <always_on>1</always_on>
          <update_rate>10</update_rate>
          <visualize>true</visualize>
          <plugin name='camera_dump' filename='libcamera_dump.so'/>
        </sensor>
      </link>

      <joint name="camera_joint" type="revolute">
        <child>camera</child>
        <parent>chassis</parent>
        <axis>
          <xyz>0 0 1</xyz>
          <limit>
            <upper>0</upper>
            <lower>0</lower>
          </limit>
        </axis>
      </joint>
      <plugin name="camera_move" filename="libcamera_move.so"/>
    </model>

    <light type="directional" name="sun" cast_shadows="true">
      <origin pose="0 0 10 0 0 0"/>
      <diffuse rgba=".8 .8 .8 1"/>
      <specular rgba=".1 .1 .1 1"/>
      <attenuation range="10" constant="0.8" linear="0.01" quadratic="0.0"/>
      <direction xyz="0 .5 -.5"/>
    </light>

  </world>
</gazebo>